Traceback (most recent call last):
  File "C:\Python37\lib\site-packages\jupyter_cache\executors\utils.py", line 56, in single_nb_execution
    record_timing=False,
  File "C:\Python37\lib\site-packages\nbclient\client.py", line 1112, in execute
    return NotebookClient(nb=nb, resources=resources, km=km, **kwargs).execute()
  File "C:\Python37\lib\site-packages\nbclient\util.py", line 74, in wrapped
    return just_run(coro(*args, **kwargs))
  File "C:\Python37\lib\site-packages\nbclient\util.py", line 53, in just_run
    return loop.run_until_complete(coro)
  File "C:\Python37\lib\asyncio\base_events.py", line 579, in run_until_complete
    return future.result()
  File "C:\Python37\lib\site-packages\nbclient\client.py", line 554, in async_execute
    cell, index, execution_count=self.code_cells_executed + 1
  File "C:\Python37\lib\site-packages\nbclient\client.py", line 857, in async_execute_cell
    self._check_raise_for_error(cell, exec_reply)
  File "C:\Python37\lib\site-packages\nbclient\client.py", line 760, in _check_raise_for_error
    raise CellExecutionError.from_cell_and_msg(cell, exec_reply_content)
nbclient.exceptions.CellExecutionError: An error occurred while executing the following cell:
------------------
import matplotlib.pyplot as plt
import numpy as np
import math

#plot 1:
x = np.linspace(0,10,1000)

def f(x):
  return x**2

plt.subplot(2, 2, 1)
plt.plot(x,f(x))
plt.title("polynomial")

#plot 2:
plt.subplot(2, 2, 2)
plt.plot(x,np.exp(x))
plt.title("exponential")

#plot 3:
plt.subplot(2, 2, 3)
plt.plot(x,np.ln(x))
plt.title("logrithm")

#plot 4:
plt.subplot(2, 2, 4)
plt.plot(x,np.sin(x))
plt.title("sin")

plt.show()
------------------

[1;31m---------------------------------------------------------------------------[0m
[1;31mAttributeError[0m                            Traceback (most recent call last)
[1;32m~\AppData\Local\Temp\ipykernel_12144\1513749687.py[0m in [0;36m<module>[1;34m[0m
[0;32m     20[0m [1;31m#plot 3:[0m[1;33m[0m[1;33m[0m[1;33m[0m[0m
[0;32m     21[0m [0mplt[0m[1;33m.[0m[0msubplot[0m[1;33m([0m[1;36m2[0m[1;33m,[0m [1;36m2[0m[1;33m,[0m [1;36m3[0m[1;33m)[0m[1;33m[0m[1;33m[0m[0m
[1;32m---> 22[1;33m [0mplt[0m[1;33m.[0m[0mplot[0m[1;33m([0m[0mx[0m[1;33m,[0m[0mnp[0m[1;33m.[0m[0mln[0m[1;33m([0m[0mx[0m[1;33m)[0m[1;33m)[0m[1;33m[0m[1;33m[0m[0m
[0m[0;32m     23[0m [0mplt[0m[1;33m.[0m[0mtitle[0m[1;33m([0m[1;34m"logrithm"[0m[1;33m)[0m[1;33m[0m[1;33m[0m[0m
[0;32m     24[0m [1;33m[0m[0m

[1;32mC:\Python37\lib\site-packages\numpy\__init__.py[0m in [0;36m__getattr__[1;34m(attr)[0m
[0;32m    312[0m [1;33m[0m[0m
[0;32m    313[0m             raise AttributeError("module {!r} has no attribute "
[1;32m--> 314[1;33m                                  "{!r}".format(__name__, attr))
[0m[0;32m    315[0m [1;33m[0m[0m
[0;32m    316[0m         [1;32mdef[0m [0m__dir__[0m[1;33m([0m[1;33m)[0m[1;33m:[0m[1;33m[0m[1;33m[0m[0m

[1;31mAttributeError[0m: module 'numpy' has no attribute 'ln'
AttributeError: module 'numpy' has no attribute 'ln'

