Traceback (most recent call last):
  File "C:\Python37\lib\site-packages\jupyter_cache\executors\utils.py", line 56, in single_nb_execution
    record_timing=False,
  File "C:\Python37\lib\site-packages\nbclient\client.py", line 1112, in execute
    return NotebookClient(nb=nb, resources=resources, km=km, **kwargs).execute()
  File "C:\Python37\lib\site-packages\nbclient\util.py", line 74, in wrapped
    return just_run(coro(*args, **kwargs))
  File "C:\Python37\lib\site-packages\nbclient\util.py", line 53, in just_run
    return loop.run_until_complete(coro)
  File "C:\Python37\lib\asyncio\base_events.py", line 579, in run_until_complete
    return future.result()
  File "C:\Python37\lib\site-packages\nbclient\client.py", line 554, in async_execute
    cell, index, execution_count=self.code_cells_executed + 1
  File "C:\Python37\lib\site-packages\nbclient\client.py", line 857, in async_execute_cell
    self._check_raise_for_error(cell, exec_reply)
  File "C:\Python37\lib\site-packages\nbclient\client.py", line 760, in _check_raise_for_error
    raise CellExecutionError.from_cell_and_msg(cell, exec_reply_content)
nbclient.exceptions.CellExecutionError: An error occurred while executing the following cell:
------------------
import matplotlib.pyplot as plt 
import numpy as np 
    
plt.rcParams["figure.figsize"] = [7.50, 3.50]
plt.rcParams["figure.autolayout"] = True

def f(x):
   return 5*(x**2)*np.cos(x^3)

x = np.linspace(-10, 10, 100)

plt.plot(x, f(x), color='red')

plt.show()
------------------

[1;31m---------------------------------------------------------------------------[0m
[1;31mTypeError[0m                                 Traceback (most recent call last)
[1;32m~\AppData\Local\Temp\ipykernel_4900\2731175160.py[0m in [0;36m<module>[1;34m[0m
[0;32m     10[0m [0mx[0m [1;33m=[0m [0mnp[0m[1;33m.[0m[0mlinspace[0m[1;33m([0m[1;33m-[0m[1;36m10[0m[1;33m,[0m [1;36m10[0m[1;33m,[0m [1;36m100[0m[1;33m)[0m[1;33m[0m[1;33m[0m[0m
[0;32m     11[0m [1;33m[0m[0m
[1;32m---> 12[1;33m [0mplt[0m[1;33m.[0m[0mplot[0m[1;33m([0m[0mx[0m[1;33m,[0m [0mf[0m[1;33m([0m[0mx[0m[1;33m)[0m[1;33m,[0m [0mcolor[0m[1;33m=[0m[1;34m'red'[0m[1;33m)[0m[1;33m[0m[1;33m[0m[0m
[0m[0;32m     13[0m [1;33m[0m[0m
[0;32m     14[0m [0mplt[0m[1;33m.[0m[0mshow[0m[1;33m([0m[1;33m)[0m[1;33m[0m[1;33m[0m[0m

[1;32m~\AppData\Local\Temp\ipykernel_4900\2731175160.py[0m in [0;36mf[1;34m(x)[0m
[0;32m      6[0m [1;33m[0m[0m
[0;32m      7[0m [1;32mdef[0m [0mf[0m[1;33m([0m[0mx[0m[1;33m)[0m[1;33m:[0m[1;33m[0m[1;33m[0m[0m
[1;32m----> 8[1;33m    [1;32mreturn[0m [1;36m5[0m[1;33m*[0m[1;33m([0m[0mx[0m[1;33m**[0m[1;36m2[0m[1;33m)[0m[1;33m*[0m[0mnp[0m[1;33m.[0m[0mcos[0m[1;33m([0m[0mx[0m[1;33m^[0m[1;36m3[0m[1;33m)[0m[1;33m[0m[1;33m[0m[0m
[0m[0;32m      9[0m [1;33m[0m[0m
[0;32m     10[0m [0mx[0m [1;33m=[0m [0mnp[0m[1;33m.[0m[0mlinspace[0m[1;33m([0m[1;33m-[0m[1;36m10[0m[1;33m,[0m [1;36m10[0m[1;33m,[0m [1;36m100[0m[1;33m)[0m[1;33m[0m[1;33m[0m[0m

[1;31mTypeError[0m: ufunc 'bitwise_xor' not supported for the input types, and the inputs could not be safely coerced to any supported types according to the casting rule ''safe''
TypeError: ufunc 'bitwise_xor' not supported for the input types, and the inputs could not be safely coerced to any supported types according to the casting rule ''safe''

