Traceback (most recent call last):
  File "C:\Python37\lib\site-packages\jupyter_cache\executors\utils.py", line 56, in single_nb_execution
    record_timing=False,
  File "C:\Python37\lib\site-packages\nbclient\client.py", line 1112, in execute
    return NotebookClient(nb=nb, resources=resources, km=km, **kwargs).execute()
  File "C:\Python37\lib\site-packages\nbclient\util.py", line 74, in wrapped
    return just_run(coro(*args, **kwargs))
  File "C:\Python37\lib\site-packages\nbclient\util.py", line 53, in just_run
    return loop.run_until_complete(coro)
  File "C:\Python37\lib\asyncio\base_events.py", line 579, in run_until_complete
    return future.result()
  File "C:\Python37\lib\site-packages\nbclient\client.py", line 554, in async_execute
    cell, index, execution_count=self.code_cells_executed + 1
  File "C:\Python37\lib\site-packages\nbclient\client.py", line 857, in async_execute_cell
    self._check_raise_for_error(cell, exec_reply)
  File "C:\Python37\lib\site-packages\nbclient\client.py", line 760, in _check_raise_for_error
    raise CellExecutionError.from_cell_and_msg(cell, exec_reply_content)
nbclient.exceptions.CellExecutionError: An error occurred while executing the following cell:
------------------
par(mfrow=c(2,1))
p = dgeom(0:10,0.2)
names(p) = 0:10
barplot(p,col="brown",main="probability mass function")
plot(ecdf(sample(1:10,size=10000,replace=TRUE, prob=p)),col="brown",main="cumulative distribution function")
------------------

Error in sample.int(length(x), size, replace, prob): incorrect number of probabilities
Traceback:

1. plot(ecdf(sample(1:10, size = 10000, replace = TRUE, prob = p)), 
 .     col = "brown", main = "cumulative distribution function")
2. ecdf(sample(1:10, size = 10000, replace = TRUE, prob = p))
3. sort(x)
4. sample(1:10, size = 10000, replace = TRUE, prob = p)
5. sample.int(length(x), size, replace, prob)
ERROR: Error in sample.int(length(x), size, replace, prob): incorrect number of probabilities


