Traceback (most recent call last):
  File "C:\Python37\lib\site-packages\jupyter_cache\executors\utils.py", line 56, in single_nb_execution
    record_timing=False,
  File "C:\Python37\lib\site-packages\nbclient\client.py", line 1112, in execute
    return NotebookClient(nb=nb, resources=resources, km=km, **kwargs).execute()
  File "C:\Python37\lib\site-packages\nbclient\util.py", line 74, in wrapped
    return just_run(coro(*args, **kwargs))
  File "C:\Python37\lib\site-packages\nbclient\util.py", line 53, in just_run
    return loop.run_until_complete(coro)
  File "C:\Python37\lib\asyncio\base_events.py", line 579, in run_until_complete
    return future.result()
  File "C:\Python37\lib\site-packages\nbclient\client.py", line 554, in async_execute
    cell, index, execution_count=self.code_cells_executed + 1
  File "C:\Python37\lib\site-packages\nbclient\client.py", line 857, in async_execute_cell
    self._check_raise_for_error(cell, exec_reply)
  File "C:\Python37\lib\site-packages\nbclient\client.py", line 760, in _check_raise_for_error
    raise CellExecutionError.from_cell_and_msg(cell, exec_reply_content)
nbclient.exceptions.CellExecutionError: An error occurred while executing the following cell:
------------------
n1=20
n2=25
mu_2 = seq(-9,9,by=0.2)
n = length(mu_2)
nsim = 1000
pvalue = 1:nsim
power = 1:n

for(j in 1:n){
  for(i in 1:nsim){
    x = rnorm(n1,mean=2,sd=1)
    y = rnorm(n2,mean=mu_2[j],sd=1)
    pvalue[i] = t.test(x, y, alternative = "two.sided")$p.value
  }
  power[j] = sum(pvalue<0.05>)
}
plot(mu_2,power,col="red",type="l",pch=16)

------------------

Error in parse(text = x, srcfile = src): <text>:15:29: unexpected '>'
14:   }
15:   power[j] = sum(pvalue<0.05>
                                ^
Traceback:

ERROR: Error in parse(text = x, srcfile = src): <text>:15:29: unexpected '>'
14:   }
15:   power[j] = sum(pvalue<0.05>
                                ^


