Traceback (most recent call last):
  File "C:\Python37\lib\site-packages\jupyter_cache\executors\utils.py", line 56, in single_nb_execution
    record_timing=False,
  File "C:\Python37\lib\site-packages\nbclient\client.py", line 1112, in execute
    return NotebookClient(nb=nb, resources=resources, km=km, **kwargs).execute()
  File "C:\Python37\lib\site-packages\nbclient\util.py", line 74, in wrapped
    return just_run(coro(*args, **kwargs))
  File "C:\Python37\lib\site-packages\nbclient\util.py", line 53, in just_run
    return loop.run_until_complete(coro)
  File "C:\Python37\lib\asyncio\base_events.py", line 579, in run_until_complete
    return future.result()
  File "C:\Python37\lib\site-packages\nbclient\client.py", line 554, in async_execute
    cell, index, execution_count=self.code_cells_executed + 1
  File "C:\Python37\lib\site-packages\nbclient\client.py", line 857, in async_execute_cell
    self._check_raise_for_error(cell, exec_reply)
  File "C:\Python37\lib\site-packages\nbclient\client.py", line 760, in _check_raise_for_error
    raise CellExecutionError.from_cell_and_msg(cell, exec_reply_content)
nbclient.exceptions.CellExecutionError: An error occurred while executing the following cell:
------------------
data=read.csv("https://book.phylolab.net/binf8441/data/Lab 1 - data.csv") 
data
data[,1] = data[,1] * 10 
write.csv(data,"newdata.csv", row.names=F) 
------------------

Error in file(file, "rt"): cannot open the connection to 'https://book.phylolab.net/binf8441/data/Lab 1 - data.csv'
Traceback:

1. read.csv("https://book.phylolab.net/binf8441/data/Lab 1 - data.csv")
2. read.table(file = file, header = header, sep = sep, quote = quote, 
 .     dec = dec, fill = fill, comment.char = comment.char, ...)
3. file(file, "rt")
ERROR: Error in file(file, "rt"): cannot open the connection to 'https://book.phylolab.net/binf8441/data/Lab 1 - data.csv'


