Traceback (most recent call last):
  File "C:\Python37\lib\site-packages\jupyter_cache\executors\utils.py", line 56, in single_nb_execution
    record_timing=False,
  File "C:\Python37\lib\site-packages\nbclient\client.py", line 1112, in execute
    return NotebookClient(nb=nb, resources=resources, km=km, **kwargs).execute()
  File "C:\Python37\lib\site-packages\nbclient\util.py", line 74, in wrapped
    return just_run(coro(*args, **kwargs))
  File "C:\Python37\lib\site-packages\nbclient\util.py", line 53, in just_run
    return loop.run_until_complete(coro)
  File "C:\Python37\lib\asyncio\base_events.py", line 579, in run_until_complete
    return future.result()
  File "C:\Python37\lib\site-packages\nbclient\client.py", line 554, in async_execute
    cell, index, execution_count=self.code_cells_executed + 1
  File "C:\Python37\lib\site-packages\nbclient\client.py", line 857, in async_execute_cell
    self._check_raise_for_error(cell, exec_reply)
  File "C:\Python37\lib\site-packages\nbclient\client.py", line 760, in _check_raise_for_error
    raise CellExecutionError.from_cell_and_msg(cell, exec_reply_content)
nbclient.exceptions.CellExecutionError: An error occurred while executing the following cell:
------------------
par(mfrow=c(3,2))
curve(dunif(x,1,3), from=1, to=3)
curve(dnorm(x,0,1), -4, 4)
curve(dexp(x,rate=4), 0, 10)
curve(dbeta(x),0,10)
curve(dgamma(x,shape=2), 0, 10)

------------------

Error in dbeta(x): argument "shape1" is missing, with no default
Traceback:

1. curve(dbeta(x), 0, 10)
2. eval(expr, envir = ll, enclos = parent.frame())
3. eval(expr, envir = ll, enclos = parent.frame())
4. dbeta(x)
ERROR: Error in dbeta(x): argument "shape1" is missing, with no default


