Traceback (most recent call last):
  File "C:\Python37\lib\site-packages\jupyter_cache\executors\utils.py", line 56, in single_nb_execution
    record_timing=False,
  File "C:\Python37\lib\site-packages\nbclient\client.py", line 1112, in execute
    return NotebookClient(nb=nb, resources=resources, km=km, **kwargs).execute()
  File "C:\Python37\lib\site-packages\nbclient\util.py", line 74, in wrapped
    return just_run(coro(*args, **kwargs))
  File "C:\Python37\lib\site-packages\nbclient\util.py", line 53, in just_run
    return loop.run_until_complete(coro)
  File "C:\Python37\lib\asyncio\base_events.py", line 579, in run_until_complete
    return future.result()
  File "C:\Python37\lib\site-packages\nbclient\client.py", line 554, in async_execute
    cell, index, execution_count=self.code_cells_executed + 1
  File "C:\Python37\lib\site-packages\nbclient\client.py", line 857, in async_execute_cell
    self._check_raise_for_error(cell, exec_reply)
  File "C:\Python37\lib\site-packages\nbclient\client.py", line 760, in _check_raise_for_error
    raise CellExecutionError.from_cell_and_msg(cell, exec_reply_content)
nbclient.exceptions.CellExecutionError: An error occurred while executing the following cell:
------------------
x = rnorm(20,mean=2,sd=1)
loglike0 = log(dnorm(x,mean=2,sd=1))
loglike1 = log(dnorm(x,mean=3,sd=1))
t = 2*loglike1 - 2loglike0
a = qchisq(0.95,df=1)
print(paste("the test statistic is",t, "\nthe critical value a =",a))
------------------

Error in parse(text = x, srcfile = src): <text>:4:19: unexpected symbol
3: loglike1 = log(dnorm(x,mean=3,sd=1))
4: t = 2*loglike1 - 2loglike0
                     ^
Traceback:

ERROR: Error in parse(text = x, srcfile = src): <text>:4:19: unexpected symbol
3: loglike1 = log(dnorm(x,mean=3,sd=1))
4: t = 2*loglike1 - 2loglike0
                     ^


