Traceback (most recent call last):
  File "C:\Python37\lib\site-packages\jupyter_cache\executors\utils.py", line 56, in single_nb_execution
    record_timing=False,
  File "C:\Python37\lib\site-packages\nbclient\client.py", line 1112, in execute
    return NotebookClient(nb=nb, resources=resources, km=km, **kwargs).execute()
  File "C:\Python37\lib\site-packages\nbclient\util.py", line 74, in wrapped
    return just_run(coro(*args, **kwargs))
  File "C:\Python37\lib\site-packages\nbclient\util.py", line 53, in just_run
    return loop.run_until_complete(coro)
  File "C:\Python37\lib\asyncio\base_events.py", line 579, in run_until_complete
    return future.result()
  File "C:\Python37\lib\site-packages\nbclient\client.py", line 554, in async_execute
    cell, index, execution_count=self.code_cells_executed + 1
  File "C:\Python37\lib\site-packages\nbclient\client.py", line 857, in async_execute_cell
    self._check_raise_for_error(cell, exec_reply)
  File "C:\Python37\lib\site-packages\nbclient\client.py", line 760, in _check_raise_for_error
    raise CellExecutionError.from_cell_and_msg(cell, exec_reply_content)
nbclient.exceptions.CellExecutionError: An error occurred while executing the following cell:
------------------
library(expm)
print(paste("the probability for time = 10", x_0 %*% (p %^% 10))
print(paste("the probability for time = 20", x_0 %*% (p %^% 20))
print(paste("the probability for time = 30", x_0 %*% (p %^% 30))
print(paste("the probability for time = 40", x_0 %*% (p %^% 40))
print(paste("the probability for time = 50", x_0 %*% (p %^% 50))
print(paste("the probability for time = 60", x_0 %*% (p %^% 60))
------------------

Error in parse(text = x, srcfile = src): <text>:3:1: unexpected symbol
2: print(paste("the probability for time = 10", x_0 %*% (p %^% 10))
3: print
   ^
Traceback:

ERROR: Error in parse(text = x, srcfile = src): <text>:3:1: unexpected symbol
2: print(paste("the probability for time = 10", x_0 %*% (p %^% 10))
3: print
   ^


